<?xml version="1.0" encoding="UTF-8"?>
<!-- Generated by org.testng.reporters.JUnitReportReporter -->
<testsuite hostname="kirubavathi" failures="1" tests="4" name="com.demowebshop.runner.TestRunnerBoth" time="8.164" errors="1" timestamp="2025-03-20T23:34:37 IST" skipped="0">
  <testcase classname="com.demowebshop.runner.TestRunnerBoth" name="runScenario" time="0.911">
    <error message="The step &#039;user should see an error message &quot;&lt;errormessage&gt;&quot;&#039; is undefined.
You can implement this step using the snippet(s) below:

@Then(&quot;user should see an error message {string}&quot;)
public void user_should_see_an_error_message(String string, io.cucumber.datatable.DataTable dataTable) {
    // Write code here that turns the phrase above into concrete actions
    // For automatic transformation, change DataTable to one of
    // E, List&lt;E&gt;, List&lt;List&lt;E&gt;&gt;, List&lt;Map&lt;K,V&gt;&gt;, Map&lt;K,V&gt; or
    // Map&lt;K, List&lt;V&gt;&gt;. E,K,V must be a String, Integer, Float,
    // Double, Byte, Short, Long, BigInteger or BigDecimal.
    //
    // For other transformations you can register a DataTableType.
    throw new io.cucumber.java.PendingException();
}
" type="io.cucumber.testng.UndefinedStepException">
      <![CDATA[io.cucumber.testng.UndefinedStepException: The step 'user should see an error message "<errormessage>"' is undefined.
You can implement this step using the snippet(s) below:

@Then("user should see an error message {string}")
public void user_should_see_an_error_message(String string, io.cucumber.datatable.DataTable dataTable) {
    // Write code here that turns the phrase above into concrete actions
    // For automatic transformation, change DataTable to one of
    // E, List<E>, List<List<E>>, List<Map<K,V>>, Map<K,V> or
    // Map<K, List<V>>. E,K,V must be a String, Integer, Float,
    // Double, Byte, Short, Long, BigInteger or BigDecimal.
    //
    // For other transformations you can register a DataTableType.
    throw new io.cucumber.java.PendingException();
}

at io.cucumber.core.runtime.TestCaseResultObserver.assertTestCasePassed(TestCaseResultObserver.java:69)
at io.cucumber.testng.TestCaseResultObserver.assertTestCasePassed(TestCaseResultObserver.java:23)
at io.cucumber.testng.TestNGCucumberRunner.lambda$runScenario$1(TestNGCucumberRunner.java:136)
at io.cucumber.core.runtime.CucumberExecutionContext.lambda$runTestCase$5(CucumberExecutionContext.java:136)
at io.cucumber.core.runtime.RethrowingThrowableCollector.executeAndThrow(RethrowingThrowableCollector.java:23)
at io.cucumber.core.runtime.CucumberExecutionContext.runTestCase(CucumberExecutionContext.java:136)
at io.cucumber.testng.TestNGCucumberRunner.runScenario(TestNGCucumberRunner.java:132)
at io.cucumber.testng.AbstractTestNGCucumberTests.runScenario(AbstractTestNGCucumberTests.java:35)
at java.base/jdk.internal.reflect.NativeMethodAccessorImpl.invoke0(Native Method)
at java.base/jdk.internal.reflect.NativeMethodAccessorImpl.invoke(NativeMethodAccessorImpl.java:77)
at java.base/jdk.internal.reflect.DelegatingMethodAccessorImpl.invoke(DelegatingMethodAccessorImpl.java:43)
at java.base/java.lang.reflect.Method.invoke(Method.java:568)
at org.testng.internal.invokers.MethodInvocationHelper.invokeMethod(MethodInvocationHelper.java:141)
at org.testng.internal.invokers.TestInvoker.invokeMethod(TestInvoker.java:686)
at org.testng.internal.invokers.TestInvoker.invokeTestMethod(TestInvoker.java:230)
at org.testng.internal.invokers.MethodRunner.runInSequence(MethodRunner.java:63)
at org.testng.internal.invokers.TestInvoker$MethodInvocationAgent.invoke(TestInvoker.java:992)
at org.testng.internal.invokers.TestInvoker.invokeTestMethods(TestInvoker.java:203)
at org.testng.internal.invokers.TestMethodWorker.invokeTestMethods(TestMethodWorker.java:154)
at org.testng.internal.invokers.TestMethodWorker.run(TestMethodWorker.java:134)
at java.base/java.util.ArrayList.forEach(ArrayList.java:1511)
at org.testng.TestRunner.privateRun(TestRunner.java:739)
at org.testng.TestRunner.run(TestRunner.java:614)
at org.testng.SuiteRunner.runTest(SuiteRunner.java:421)
at org.testng.SuiteRunner.runSequentially(SuiteRunner.java:413)
at org.testng.SuiteRunner.privateRun(SuiteRunner.java:373)
at org.testng.SuiteRunner.run(SuiteRunner.java:312)
at org.testng.SuiteRunnerWorker.runSuite(SuiteRunnerWorker.java:52)
at org.testng.SuiteRunnerWorker.run(SuiteRunnerWorker.java:95)
at org.testng.TestNG.runSuitesSequentially(TestNG.java:1274)
at org.testng.TestNG.runSuitesLocally(TestNG.java:1208)
at org.testng.TestNG.runSuites(TestNG.java:1112)
at org.testng.TestNG.run(TestNG.java:1079)
at org.testng.remote.AbstractRemoteTestNG.run(AbstractRemoteTestNG.java:115)
at org.testng.remote.RemoteTestNG.initAndRun(RemoteTestNG.java:293)
at org.testng.remote.RemoteTestNG.main(RemoteTestNG.java:91)
]]>
    </error>
  </testcase> <!-- runScenario -->
  <testcase classname="com.demowebshop.runner.TestRunnerBoth" name="runScenario" time="3.144"/>
  <testcase classname="com.demowebshop.runner.TestRunnerBoth" name="runScenario" time="2.947"/>
  <testcase classname="com.demowebshop.runner.TestRunnerBoth" name="runScenario" time="1.162">
    <failure message="Error message was not displayed expected [true] but found [false]" type="java.lang.AssertionError">
      <![CDATA[java.lang.AssertionError: Error message was not displayed expected [true] but found [false]
at org.testng.Assert.fail(Assert.java:111)
at org.testng.Assert.failNotEquals(Assert.java:1578)
at org.testng.Assert.assertTrue(Assert.java:57)
at com.demowebshop.stepdefinition.RegistrationLoginSteps.an_error_message_should_be_displayed_saying(RegistrationLoginSteps.java:149)
at âœ½.an error message should be displayed saying "Login was unsuccessful. Please correct the errors and try again. The credentials provided are incorrect."(file:///D:/JAVA%20PRACTISE%20PROGRAMS/WIPRO%20-%20SELENIUM/CapstoneProject%20-%20DemoWebShop/src/test/resources/features/DwsLoginRegister.feature:60)
]]>
    </failure>
  </testcase> <!-- runScenario -->
</testsuite> <!-- com.demowebshop.runner.TestRunnerBoth -->
